<?xml version="1.0"?>
<robot name='vision60'>
    <link name='body'>
        <pose frame=''>0 0 0 0 -0 0</pose>
        <inertial>
            <pose frame=''>0 0 0 0 -0 0</pose>
            <mass>17.9</mass>
            <inertia>
                <ixx>0.0986</ixx>
                <ixy>0</ixy>
                <ixz>0</ixz>
                <iyy>0.8105</iyy>
                <iyz>0</iyz>
                <izz>0.8369</izz>
            </inertia>
        </inertial>
        <collision name='body_collision'>
            <pose frame=''>0 0 0 0 -0 0</pose>
            <geometry>
                <box>
                    <size>0.83 0.25 0.19</size>
                </box>
            </geometry>
            <surface>
                <contact>
                    <ode/>
                </contact>
                <friction>
                    <ode/>
                </friction>
            </surface>
        </collision>
        <visual name='body_visual'>
            <pose frame=''>0 0 0 0 -0 0</pose>
            <geometry>
                <box>
                    <size>0.83 0.25 0.19</size>
                </box>
            </geometry>
            <material>
                <script>
                    <name>Gazebo/BlackTransparent</name>
                    <uri>file://media/materials/scripts/gazebo.material</uri>
                </script>
            </material>
        </visual>
        <gravity>1</gravity>

    </link>
    <link name='hip0'>
        <pose frame=''>0.34385 0.092865 0 0 -0 0</pose>
        <inertial>
            <pose frame=''>0 0 0 0 -0 0</pose>
            <mass>1.975</mass>
            <inertia>
                <ixx>0.00891458</ixx>
                <ixy>0</ixy>
                <ixz>0</ixz>
                <iyy>0.0100573</iyy>
                <iyz>0</iyz>
                <izz>0.015337</izz>
            </inertia>
        </inertial>
        <collision name='hip0_collision'>
            <pose frame=''>-0.01 -0.005 0 1.5708 -0 0</pose>
            <geometry>
                <box>
                    <size>0.15 0.09 0.15</size>
                </box>
            </geometry>
            <surface>
                <contact>
                    <ode/>
                </contact>
                <friction>
                    <ode/>
                </friction>
            </surface>
        </collision>
        <visual name='hip0_visual'>
            <pose frame=''>-0.01 -0.005 0 1.5708 -0 0</pose>
            <geometry>
                <box>
                    <size>0.15 0.09 0.15</size>
                </box>
            </geometry>
            <material>
                <script>
                    <name>Gazebo/Purple</name>
                    <uri>file://media/materials/scripts/gazebo.material</uri>
                </script>
            </material>
        </visual>
        <gravity>1</gravity>
        <velocity_decay/>
    </link>
    <joint name='body_hip' type='revolute'>
        <child>hip0</child>
        <parent>body</parent>
        <axis>
            <xyz>1 0 0</xyz>
            <limit>
                <lower>-0.43</lower>
                <upper>0.43</upper>
                <effort>375</effort>
                <velocity>8.6</velocity>
            </limit>
            <dynamics>
                <damping>0</damping>
                <friction>0</friction>
                <spring_reference>0</spring_reference>
                <spring_stiffness>0</spring_stiffness>
            </dynamics>
            <use_parent_model_frame>1</use_parent_model_frame>
        </axis>
    </joint>
    <link name='upper0'>
        <pose frame=''>0.34385 0.190365 0 0 -0 0</pose>
        <inertial>
            <pose frame=''>0 0 0 0 -0 0</pose>
            <mass>2.525</mass>
            <inertia>
                <ixx>0.0003125</ixx>
                <ixy>0</ixy>
                <ixz>0</ixz>
                <iyy>0.0040625</iyy>
                <iyz>0</iyz>
                <izz>0.0040625</izz>
            </inertia>
        </inertial>
        <collision name='upper0_collision'>
            <pose frame=''>-0.17 0 0 0 -0 0</pose>
            <geometry>
                <box>
                    <size>0.34 0.055 0.075</size>
                </box>
            </geometry>
            <surface>
                <contact>
                    <ode/>
                </contact>
                <friction>
                    <ode/>
                </friction>
            </surface>
        </collision>
        <visual name='upper0_visual'>
            <pose frame=''>-0.17 0 0 0 -0 0</pose>
            <geometry>
                <box>
                    <size>0.34 0.055 0.075</size>
                </box>
            </geometry>
            <material>
                <script>
                    <name>Gazebo/Blue</name>
                    <uri>file://media/materials/scripts/gazebo.material</uri>
                </script>
            </material>
        </visual>
        <gravity>1</gravity>
        <velocity_decay/>
    </link>
    <joint name='hip_upper' type='revolute'>
        <child>upper0</child>
        <parent>hip0</parent>
        <axis>
            <xyz>0 -1 0</xyz>
            <limit>
                <lower>-6.28319</lower>
                <upper>6.28319</upper>
                <effort>87.5</effort>
                <velocity>30</velocity>
            </limit>
            <dynamics>
                <damping>0</damping>
                <friction>0</friction>
                <spring_reference>0</spring_reference>
                <spring_stiffness>0</spring_stiffness>
            </dynamics>
            <use_parent_model_frame>1</use_parent_model_frame>
        </axis>
    </joint>
    <link name='lower0'>
        <pose frame=''>0.00385 0.190365 0 0 -0 0</pose>
        <inertial>
            <pose frame=''>0.097343 0 0 0 -0 0</pose>
            <mass>0.525</mass>
            <inertia>
                <ixx>0.00133575</ixx>
                <ixy>0</ixy>
                <ixz>0</ixz>
                <iyy>0.0137725</iyy>
                <iyz>0</iyz>
                <izz>0.0125618</izz>
            </inertia>
        </inertial>
        <collision name='lower0_collision'>
            <pose frame=''>0.17035 0 0 3.14159 1.57079 3.14159</pose>
            <geometry>
                <cylinder>
                    <length>0.3407</length>
                    <radius>0.02</radius>
                </cylinder>
            </geometry>
            <surface>
                <contact>
                    <ode/>
                </contact>
                <friction>
                    <ode/>
                </friction>
            </surface>
        </collision>
        <collision name='lower0_fixed_joint_lump__toe0_collision_1'>
            <pose frame=''>0.3407 0 0 0 -0 0</pose>
            <geometry>
                <sphere>
                    <radius>0.0325</radius>
                </sphere>
            </geometry>
            <surface>
                <bounce>
                    <restitution_coefficient>0</restitution_coefficient>
                    <threshold>1e+06</threshold>
                </bounce>
                <friction>
                    <torsional>
                        <coefficient>0.3</coefficient>
                    </torsional>
                    <ode>
                        <mu>20</mu>
                        <mu2>10</mu2>
                    </ode>
                    <bullet>
                        <rolling_friction>0.3</rolling_friction>
                        <friction2>10</friction2>
                    </bullet>
                </friction>
                <contact>
                    <bullet>
                        <kp>30000</kp>
                        <kd>1000</kd>
                        <split_impulse>1</split_impulse>
                        <split_impulse_penetration_threshold>-0.01</split_impulse_penetration_threshold>
                    </bullet>
                    <ode>
                        <kp>30000</kp>
                        <kd>1000</kd>
                    </ode>
                </contact>
            </surface>
        </collision>
        <visual name='lower0_visual'>
            <pose frame=''>0.17035 0 0 3.14159 1.57079 3.14159</pose>
            <geometry>
                <cylinder>
                    <length>0.3407</length>
                    <radius>0.02</radius>
                </cylinder>
            </geometry>
            <material>
                <script>
                    <name>Gazebo/Black</name>
                    <uri>file://media/materials/scripts/gazebo.material</uri>
                </script>
            </material>
        </visual>
        <visual name='lower0_fixed_joint_lump__toe0_visual_1'>
            <pose frame=''>0.3407 0 0 0 -0 0</pose>
            <geometry>
                <sphere>
                    <radius>0.0325</radius>
                </sphere>
            </geometry>
            <material>
                <script>
                    <name>Gazebo/DarkGray</name>
                    <uri>file://media/materials/scripts/gazebo.material</uri>
                </script>
            </material>
        </visual>
        <velocity_decay/>
        <gravity>1</gravity>
        <velocity_decay/>
    </link>
    <joint name='upper_lower' type='revolute'>
        <child>lower0</child>
        <parent>upper0</parent>
        <axis>
            <xyz>0 1 0</xyz>
            <limit>
                <lower>0</lower>
                <upper>3.14159</upper>
                <effort>87.5</effort>
                <velocity>30</velocity>
            </limit>
            <dynamics>
                <damping>0</damping>
                <friction>0</friction>
                <spring_reference>0</spring_reference>
                <spring_stiffness>0</spring_stiffness>
            </dynamics>
            <use_parent_model_frame>1</use_parent_model_frame>
        </axis>
    </joint>

    <transmission type="SimpleTransmission" name="u1">
        <actuator name="motor_one"/>
        <joint name="body_hip"/>
        <mechanicalReduction>1</mechanicalReduction>
    </transmission>
    <transmission type="SimpleTransmission" name="u2">
        <actuator name="motor_two"/>
        <joint name="hip_upper"/>
        <mechanicalReduction>1</mechanicalReduction>
    </transmission>
    <transmission type="SimpleTransmission" name="u3">
        <actuator name="motor_three"/>
        <joint name="upper_lower"/>
        <mechanicalReduction>1</mechanicalReduction>
    </transmission>

</robot>
