<?xml version="1.0"?>
<robot name='vision60'>
    <link name='body'>
        <visual name='body_visual'>
                <geometry>
                    <mesh filename="mesh/Frame.obj" scale="1 1 1"/>
                </geometry>
            <material name="gray">
                <color rgba="0.5 0.5 0.5 1"/>
            </material>
        </visual>
    </link>
    <link name='hip0'>
        <inertial>
            <origin xyz="0.40 0.02 0.085" rpy="0 3.14 0"/>
            <mass value="1.975">1.975</mass>
            <inertia ixx="0.00891458" ixy="0" ixz="0" iyz="0" iyy="0.0100573" izz="0.015337">
                <ixx>0.00891458</ixx>
                <ixy>0</ixy>
                <ixz>0</ixz>
                <iyy>0.0100573</iyy>
                <iyz>0</iyz>
                <izz>0.015337</izz>
            </inertia>
        </inertial>
        <visual name='hip0_visual'>
            <origin xyz="0.40 0.02 0.085" rpy="0 3.14 0"/>
            <geometry>
<!--                <box size="0.15 0.09 0.15">-->
<!--                    <size>0.15 0.09 0.15</size>-->
<!--                </box>-->
                <mesh filename="mesh/Hip_Pod_Assembly.obj" scale="1 1 1"/>
            </geometry>
            <material name="gray">
                <color rgba="0.5 0.5 0.5 1"/>
            </material>
        </visual>
    </link>
    <joint name="base_weld" type="fixed">
        <parent link="world"/>
        <child link="body"/>
    </joint>
    <joint name='body_hip' type='continuous'>
        <child link="hip0">hip0</child>
        <parent link="body">body</parent>
        <axis xyz="1 0 0">
            <xyz>1 0 0</xyz>
            <limit effort="375">
                <lower>-0.43</lower>
                <upper>0.43</upper>
                <effort>375</effort>
                <velocity>8.6</velocity>
            </limit>
            <dynamics damping="0.0">
                <damping>0</damping>
                <friction>0</friction>
                <spring_reference>0</spring_reference>
                <spring_stiffness>0</spring_stiffness>
            </dynamics>
<!--            <use_parent_model_frame>1</use_parent_model_frame>-->
        </axis>
    </joint>
    <link name='upper0'>
        <inertial>
            <origin xyz="0.40 0.190365 0.085" rpy="3.14 -0 0"/>
            <mass value="2.525">2.525</mass>
            <inertia ixx="0.0003125" ixy="0" ixz="0" iyz="0" iyy="0.0040625" izz="0.0040625">
                <ixx>0.0003125</ixx>
                <ixy>0</ixy>
                <ixz>0</ixz>
                <iyy>0.0040625</iyy>
                <iyz>0</iyz>
                <izz>0.0040625</izz>
            </inertia>
        </inertial>
        <visual name='upper0_visual'>
            <origin xyz="0.40 0.190365 0.085" rpy="3.14 -0 0"/>
            <geometry>
<!--                <box size="0.34 0.055 0.075">-->
<!--                    <size>0.34 0.055 0.075</size>-->
<!--                </box>-->
                <mesh filename="mesh/Leg_Assembly.obj" scale=".001 .001 .001"/>
            </geometry>
            <material name="gray">
                <color rgba="0.5 0.5 0.5 1"/>
            </material>
        </visual>
    </link>
    <joint name='hip_upper' type='continuous'>
        <child link="upper0">upper0</child>
        <parent link="hip0">hip0</parent>
        <axis xyz="0 -1 0">
            <xyz>0 -1 0</xyz>
            <limit effort="87.5">
                <lower>-6.28319</lower>
                <upper>6.28319</upper>
                <effort>87.5</effort>
                <velocity>30</velocity>
            </limit>
            <dynamics damping="0.0">
                <damping>0</damping>
                <friction>0</friction>
                <spring_reference>0</spring_reference>
                <spring_stiffness>0</spring_stiffness>
            </dynamics>
<!--            <use_parent_model_frame>1</use_parent_model_frame>-->
        </axis>
    </joint>
    <link name='lower0'>
        <pose frame=''>0.00385 0.190365 0 0 -0 0</pose>
        <inertial>
            <origin frame='lower0' xyz="0.00385 0.190365 0" rpy="0 -0 0"/>
            <pose frame=''>0.097343 0 0 0 -0 0</pose>
            <mass value="0.525">0.525</mass>
            <inertia ixx="0.00133575" ixy="0" ixz="0" iyz="0" iyy="0.0137725" izz="0.0125618">
                <ixx>0.00133575</ixx>
                <ixy>0</ixy>
                <ixz>0</ixz>
                <iyy>0.0137725</iyy>
                <iyz>0</iyz>
                <izz>0.0125618</izz>
            </inertia>
        </inertial>
        <visual name='lower0_visual'>
            <origin xyz="0.00385 0.190365 0" rpy="0 -0 0"/>
            <pose frame=''>0.17035 0 0 3.14159 1.57079 3.14159</pose>
            <geometry>
<!--                <cylinder length="0.3407" radius="0.02">-->
<!--                    <length>0.3407</length>-->
<!--                    <radius>0.02</radius>-->
<!--                </cylinder>-->
                <mesh filename="mesh/Lower_Leg_Assembly.obj" scale=".001 .001 .001"/>
            </geometry>
            <material name="gray">
                <color rgba="0.5 0.5 0.5 1"/>
            </material>
        </visual>
    </link>
    <joint name='upper_lower' type='continuous'>
        <child link="lower0">lower0</child>
        <parent link="upper0">upper0</parent>
        <axis xyz="0 1 0">
            <xyz>0 1 0</xyz>
            <limit effort="87.5">
                <lower>0</lower>
                <upper>3.14159</upper>
                <effort>87.5</effort>
                <velocity>30</velocity>
            </limit>
            <dynamics damping="0.0">
                <damping>0</damping>
                <friction>0</friction>
                <spring_reference>0</spring_reference>
                <spring_stiffness>0</spring_stiffness>
            </dynamics>
<!--            <use_parent_model_frame>1</use_parent_model_frame>-->
        </axis>
    </joint>

    <transmission type="SimpleTransmission" name="u1">
        <actuator name="motor_one"/>
        <joint name="body_hip"/>
        <mechanicalReduction>1</mechanicalReduction>
    </transmission>
    <transmission type="SimpleTransmission" name="u2">
        <actuator name="motor_two"/>
        <joint name="hip_upper"/>
        <mechanicalReduction>1</mechanicalReduction>
    </transmission>
    <transmission type="SimpleTransmission" name="u3">
        <actuator name="motor_three"/>
        <joint name="upper_lower"/>
        <mechanicalReduction>1</mechanicalReduction>
    </transmission>

</robot>
